[2023-07-03T07:11:42.924+0200] {taskinstance.py:1103} INFO - Dependencies all met for dep_context=non-requeueable deps ti=<TaskInstance: execute_python.save_container_info manual__2023-07-03T05:10:58.972507+00:00 [queued]>
[2023-07-03T07:11:42.936+0200] {taskinstance.py:1103} INFO - Dependencies all met for dep_context=requeueable deps ti=<TaskInstance: execute_python.save_container_info manual__2023-07-03T05:10:58.972507+00:00 [queued]>
[2023-07-03T07:11:42.937+0200] {taskinstance.py:1308} INFO - Starting attempt 1 of 2
[2023-07-03T07:11:42.957+0200] {taskinstance.py:1327} INFO - Executing <Task(PythonOperator): save_container_info> on 2023-07-03 05:10:58.972507+00:00
[2023-07-03T07:11:42.961+0200] {standard_task_runner.py:57} INFO - Started process 653176 to run task
[2023-07-03T07:11:42.965+0200] {standard_task_runner.py:84} INFO - Running: ['airflow', 'tasks', 'run', 'execute_python', 'save_container_info', 'manual__2023-07-03T05:10:58.972507+00:00', '--job-id', '348', '--raw', '--subdir', 'DAGS_FOLDER/thesis_container.py', '--cfg-path', '/tmp/tmpd48zei99']
[2023-07-03T07:11:42.967+0200] {standard_task_runner.py:85} INFO - Job 348: Subtask save_container_info
[2023-07-03T07:11:43.004+0200] {task_command.py:410} INFO - Running <TaskInstance: execute_python.save_container_info manual__2023-07-03T05:10:58.972507+00:00 [running]> on host DESKTOP-3KJU1M7.
[2023-07-03T07:11:43.104+0200] {taskinstance.py:1545} INFO - Exporting env vars: AIRFLOW_CTX_DAG_OWNER='airflow' AIRFLOW_CTX_DAG_ID='execute_python' AIRFLOW_CTX_TASK_ID='save_container_info' AIRFLOW_CTX_EXECUTION_DATE='2023-07-03T05:10:58.972507+00:00' AIRFLOW_CTX_TRY_NUMBER='1' AIRFLOW_CTX_DAG_RUN_ID='manual__2023-07-03T05:10:58.972507+00:00'
[2023-07-03T07:11:43.106+0200] {taskinstance.py:1824} ERROR - Task failed with exception
Traceback (most recent call last):
  File "/home/reynel1995/thesis/lib/python3.10/site-packages/airflow/operators/python.py", line 181, in execute
    return_value = self.execute_callable()
  File "/home/reynel1995/thesis/lib/python3.10/site-packages/airflow/operators/python.py", line 198, in execute_callable
    return self.python_callable(*self.op_args, **self.op_kwargs)
  File "/home/reynel1995/airflow/dags/thesis_container.py", line 323, in save_container_info
    f.write(f"{username} - {process_selection} - {file_path}\n")
UnboundLocalError: local variable 'file_path' referenced before assignment
[2023-07-03T07:11:43.110+0200] {taskinstance.py:1345} INFO - Marking task as UP_FOR_RETRY. dag_id=execute_python, task_id=save_container_info, execution_date=20230703T051058, start_date=20230703T051142, end_date=20230703T051143
[2023-07-03T07:11:43.124+0200] {standard_task_runner.py:104} ERROR - Failed to execute job 348 for task save_container_info (local variable 'file_path' referenced before assignment; 653176)
[2023-07-03T07:11:43.137+0200] {local_task_job_runner.py:225} INFO - Task exited with return code 1
[2023-07-03T07:11:43.188+0200] {taskinstance.py:2651} INFO - 0 downstream tasks scheduled from follow-on schedule check
