[2023-07-07T13:32:34.876+0200] {taskinstance.py:1103} INFO - Dependencies all met for dep_context=non-requeueable deps ti=<TaskInstance: execute_python.execute_command_in_containers manual__2023-07-05T03:56:32.740955+00:00 [queued]>
[2023-07-07T13:32:34.896+0200] {taskinstance.py:1103} INFO - Dependencies all met for dep_context=requeueable deps ti=<TaskInstance: execute_python.execute_command_in_containers manual__2023-07-05T03:56:32.740955+00:00 [queued]>
[2023-07-07T13:32:34.908+0200] {taskinstance.py:1308} INFO - Starting attempt 16 of 16
[2023-07-07T13:32:34.964+0200] {taskinstance.py:1327} INFO - Executing <Task(PythonOperator): execute_command_in_containers> on 2023-07-05 03:56:32.740955+00:00
[2023-07-07T13:32:34.969+0200] {standard_task_runner.py:57} INFO - Started process 485443 to run task
[2023-07-07T13:32:34.973+0200] {standard_task_runner.py:84} INFO - Running: ['airflow', 'tasks', 'run', 'execute_python', 'execute_command_in_containers', 'manual__2023-07-05T03:56:32.740955+00:00', '--job-id', '719', '--raw', '--subdir', 'DAGS_FOLDER/thesis_container.py', '--cfg-path', '/tmp/tmpqk0n5iia']
[2023-07-07T13:32:34.975+0200] {standard_task_runner.py:85} INFO - Job 719: Subtask execute_command_in_containers
[2023-07-07T13:32:35.046+0200] {task_command.py:410} INFO - Running <TaskInstance: execute_python.execute_command_in_containers manual__2023-07-05T03:56:32.740955+00:00 [running]> on host DESKTOP-3KJU1M7.
[2023-07-07T13:32:35.156+0200] {taskinstance.py:1545} INFO - Exporting env vars: AIRFLOW_CTX_DAG_OWNER='airflow' AIRFLOW_CTX_DAG_ID='execute_python' AIRFLOW_CTX_TASK_ID='execute_command_in_containers' AIRFLOW_CTX_EXECUTION_DATE='2023-07-05T03:56:32.740955+00:00' AIRFLOW_CTX_TRY_NUMBER='16' AIRFLOW_CTX_DAG_RUN_ID='manual__2023-07-05T03:56:32.740955+00:00'
[2023-07-07T13:32:45.511+0200] {taskinstance.py:1824} ERROR - Task failed with exception
Traceback (most recent call last):
  File "/home/reynel1995/thesis/lib/python3.10/site-packages/airflow/operators/python.py", line 181, in execute
    return_value = self.execute_callable()
  File "/home/reynel1995/thesis/lib/python3.10/site-packages/airflow/operators/python.py", line 198, in execute_callable
    return self.python_callable(*self.op_args, **self.op_kwargs)
  File "/home/reynel1995/airflow/dags/thesis_container.py", line 255, in execute_command_in_containers
    data = json.loads(output)
  File "/usr/lib/python3.10/json/__init__.py", line 346, in loads
    return _default_decoder.decode(s)
  File "/usr/lib/python3.10/json/decoder.py", line 340, in decode
    raise JSONDecodeError("Extra data", s, end)
json.decoder.JSONDecodeError: Extra data: line 1 column 5 (char 4)
[2023-07-07T13:32:45.518+0200] {taskinstance.py:1345} INFO - Marking task as FAILED. dag_id=execute_python, task_id=execute_command_in_containers, execution_date=20230705T035632, start_date=20230707T113234, end_date=20230707T113245
[2023-07-07T13:32:45.536+0200] {standard_task_runner.py:104} ERROR - Failed to execute job 719 for task execute_command_in_containers (Extra data: line 1 column 5 (char 4); 485443)
[2023-07-07T13:32:45.581+0200] {local_task_job_runner.py:225} INFO - Task exited with return code 1
[2023-07-07T13:32:45.620+0200] {taskinstance.py:2651} INFO - 0 downstream tasks scheduled from follow-on schedule check
