[2023-07-02T22:34:57.630+0200] {taskinstance.py:1103} INFO - Dependencies all met for dep_context=non-requeueable deps ti=<TaskInstance: execute_python.save_container_info manual__2023-06-30T05:23:02.005147+00:00 [queued]>
[2023-07-02T22:34:57.643+0200] {taskinstance.py:1103} INFO - Dependencies all met for dep_context=requeueable deps ti=<TaskInstance: execute_python.save_container_info manual__2023-06-30T05:23:02.005147+00:00 [queued]>
[2023-07-02T22:34:57.643+0200] {taskinstance.py:1308} INFO - Starting attempt 2 of 2
[2023-07-02T22:34:57.662+0200] {taskinstance.py:1327} INFO - Executing <Task(PythonOperator): save_container_info> on 2023-06-30 05:23:02.005147+00:00
[2023-07-02T22:34:57.667+0200] {standard_task_runner.py:57} INFO - Started process 647246 to run task
[2023-07-02T22:34:57.671+0200] {standard_task_runner.py:84} INFO - Running: ['airflow', 'tasks', 'run', 'execute_python', 'save_container_info', 'manual__2023-06-30T05:23:02.005147+00:00', '--job-id', '329', '--raw', '--subdir', 'DAGS_FOLDER/thesis_container.py', '--cfg-path', '/tmp/tmpchutsxrm']
[2023-07-02T22:34:57.673+0200] {standard_task_runner.py:85} INFO - Job 329: Subtask save_container_info
[2023-07-02T22:34:57.721+0200] {task_command.py:410} INFO - Running <TaskInstance: execute_python.save_container_info manual__2023-06-30T05:23:02.005147+00:00 [running]> on host DESKTOP-3KJU1M7.
[2023-07-02T22:34:57.816+0200] {taskinstance.py:1545} INFO - Exporting env vars: AIRFLOW_CTX_DAG_OWNER='airflow' AIRFLOW_CTX_DAG_ID='execute_python' AIRFLOW_CTX_TASK_ID='save_container_info' AIRFLOW_CTX_EXECUTION_DATE='2023-06-30T05:23:02.005147+00:00' AIRFLOW_CTX_TRY_NUMBER='2' AIRFLOW_CTX_DAG_RUN_ID='manual__2023-06-30T05:23:02.005147+00:00'
[2023-07-02T22:34:57.817+0200] {taskinstance.py:1824} ERROR - Task failed with exception
Traceback (most recent call last):
  File "/home/reynel1995/thesis/lib/python3.10/site-packages/airflow/operators/python.py", line 181, in execute
    return_value = self.execute_callable()
  File "/home/reynel1995/thesis/lib/python3.10/site-packages/airflow/operators/python.py", line 198, in execute_callable
    return self.python_callable(*self.op_args, **self.op_kwargs)
TypeError: save_container_info() missing 1 required positional argument: 'file_path'
[2023-07-02T22:34:57.822+0200] {taskinstance.py:1345} INFO - Marking task as FAILED. dag_id=execute_python, task_id=save_container_info, execution_date=20230630T052302, start_date=20230702T203457, end_date=20230702T203457
[2023-07-02T22:34:57.838+0200] {standard_task_runner.py:104} ERROR - Failed to execute job 329 for task save_container_info (save_container_info() missing 1 required positional argument: 'file_path'; 647246)
[2023-07-02T22:34:57.844+0200] {local_task_job_runner.py:225} INFO - Task exited with return code 1
[2023-07-02T22:34:57.881+0200] {taskinstance.py:2651} INFO - 0 downstream tasks scheduled from follow-on schedule check
