[2023-07-02T22:33:55.484+0200] {taskinstance.py:1103} INFO - Dependencies all met for dep_context=non-requeueable deps ti=<TaskInstance: execute_python.save_container_info manual__2023-06-30T05:23:02.005147+00:00 [queued]>
[2023-07-02T22:33:55.495+0200] {taskinstance.py:1103} INFO - Dependencies all met for dep_context=requeueable deps ti=<TaskInstance: execute_python.save_container_info manual__2023-06-30T05:23:02.005147+00:00 [queued]>
[2023-07-02T22:33:55.496+0200] {taskinstance.py:1308} INFO - Starting attempt 1 of 2
[2023-07-02T22:33:55.523+0200] {taskinstance.py:1327} INFO - Executing <Task(PythonOperator): save_container_info> on 2023-06-30 05:23:02.005147+00:00
[2023-07-02T22:33:55.527+0200] {standard_task_runner.py:57} INFO - Started process 646851 to run task
[2023-07-02T22:33:55.530+0200] {standard_task_runner.py:84} INFO - Running: ['airflow', 'tasks', 'run', 'execute_python', 'save_container_info', 'manual__2023-06-30T05:23:02.005147+00:00', '--job-id', '324', '--raw', '--subdir', 'DAGS_FOLDER/thesis_container.py', '--cfg-path', '/tmp/tmpsd2d8ld8']
[2023-07-02T22:33:55.532+0200] {standard_task_runner.py:85} INFO - Job 324: Subtask save_container_info
[2023-07-02T22:33:55.575+0200] {task_command.py:410} INFO - Running <TaskInstance: execute_python.save_container_info manual__2023-06-30T05:23:02.005147+00:00 [running]> on host DESKTOP-3KJU1M7.
[2023-07-02T22:33:55.675+0200] {taskinstance.py:1545} INFO - Exporting env vars: AIRFLOW_CTX_DAG_OWNER='airflow' AIRFLOW_CTX_DAG_ID='execute_python' AIRFLOW_CTX_TASK_ID='save_container_info' AIRFLOW_CTX_EXECUTION_DATE='2023-06-30T05:23:02.005147+00:00' AIRFLOW_CTX_TRY_NUMBER='1' AIRFLOW_CTX_DAG_RUN_ID='manual__2023-06-30T05:23:02.005147+00:00'
[2023-07-02T22:33:55.677+0200] {taskinstance.py:1824} ERROR - Task failed with exception
Traceback (most recent call last):
  File "/home/reynel1995/thesis/lib/python3.10/site-packages/airflow/operators/python.py", line 181, in execute
    return_value = self.execute_callable()
  File "/home/reynel1995/thesis/lib/python3.10/site-packages/airflow/operators/python.py", line 198, in execute_callable
    return self.python_callable(*self.op_args, **self.op_kwargs)
TypeError: save_container_info() missing 1 required positional argument: 'file_path'
[2023-07-02T22:33:55.684+0200] {taskinstance.py:1345} INFO - Marking task as UP_FOR_RETRY. dag_id=execute_python, task_id=save_container_info, execution_date=20230630T052302, start_date=20230702T203355, end_date=20230702T203355
[2023-07-02T22:33:55.704+0200] {standard_task_runner.py:104} ERROR - Failed to execute job 324 for task save_container_info (save_container_info() missing 1 required positional argument: 'file_path'; 646851)
[2023-07-02T22:33:55.743+0200] {local_task_job_runner.py:225} INFO - Task exited with return code 1
[2023-07-02T22:33:55.781+0200] {taskinstance.py:2651} INFO - 0 downstream tasks scheduled from follow-on schedule check
